2025-05-29 09:38:45,538 - __main__ - INFO - Starting WinForms application test...
2025-05-29 09:38:45,539 - __main__ - INFO - 1. Creating Windows driver...
2025-05-29 09:38:45,539 - windows_automation.windows_driver_factory - INFO - Creating Windows driver...
2025-05-29 09:38:45,539 - windows_automation.windows_driver_factory - INFO - Setting app path: C:\Code\New folder\WinFormsApp2\bin\ARM32\Debug\net8.0-windows\WinFormsApp2.exe
2025-05-29 09:38:45,539 - windows_automation.windows_driver_factory - INFO - Setting capability platformName: Windows
2025-05-29 09:38:45,540 - windows_automation.windows_driver_factory - INFO - Setting capability automationName: Windows
2025-05-29 09:38:45,540 - windows_automation.windows_driver_factory - INFO - Setting capability deviceName: WindowsPC
2025-05-29 09:38:45,540 - windows_automation.windows_driver_factory - INFO - Setting capability app: C:\\Code\\New folder\\WinFormsApp2\\bin\\ARM32\\Debug\\net8.0-windows\\WinFormsApp2.exe
2025-05-29 09:38:45,540 - windows_automation.windows_driver_factory - INFO - Connecting to Appium Windows Driver at http://127.0.0.1:4721
2025-05-29 09:38:47,593 - urllib3.connectionpool - WARNING - Retrying (Retry(total=2, connect=None, read=None, redirect=None, status=None)) after connection broken by 'NewConnectionError('<urllib3.connection.HTTPConnection object at 0x0000021FB3B56510>: Failed to establish a new connection: [WinError 10061] No connection could be made because the target machine actively refused it')': /session
2025-05-29 09:38:49,646 - urllib3.connectionpool - WARNING - Retrying (Retry(total=1, connect=None, read=None, redirect=None, status=None)) after connection broken by 'NewConnectionError('<urllib3.connection.HTTPConnection object at 0x0000021FB3B6B390>: Failed to establish a new connection: [WinError 10061] No connection could be made because the target machine actively refused it')': /session
2025-05-29 09:38:51,700 - urllib3.connectionpool - WARNING - Retrying (Retry(total=0, connect=None, read=None, redirect=None, status=None)) after connection broken by 'NewConnectionError('<urllib3.connection.HTTPConnection object at 0x0000021FB3B6B750>: Failed to establish a new connection: [WinError 10061] No connection could be made because the target machine actively refused it')': /session
2025-05-29 09:38:53,758 - windows_automation.windows_driver_factory - ERROR - Failed to create remote Windows driver: HTTPConnectionPool(host='127.0.0.1', port=4721): Max retries exceeded with url: /session (Caused by NewConnectionError('<urllib3.connection.HTTPConnection object at 0x0000021FB3B59CD0>: Failed to establish a new connection: [WinError 10061] No connection could be made because the target machine actively refused it'))
2025-05-29 09:38:53,758 - windows_automation.windows_driver_factory - ERROR - Failed to create Windows driver: HTTPConnectionPool(host='127.0.0.1', port=4721): Max retries exceeded with url: /session (Caused by NewConnectionError('<urllib3.connection.HTTPConnection object at 0x0000021FB3B59CD0>: Failed to establish a new connection: [WinError 10061] No connection could be made because the target machine actively refused it'))
2025-05-29 09:38:53,758 - __main__ - ERROR - Test failed with error: HTTPConnectionPool(host='127.0.0.1', port=4721): Max retries exceeded with url: /session (Caused by NewConnectionError('<urllib3.connection.HTTPConnection object at 0x0000021FB3B59CD0>: Failed to establish a new connection: [WinError 10061] No connection could be made because the target machine actively refused it'))
Traceback (most recent call last):
  File "C:\Users\RohanThomas\AppData\Local\Packages\PythonSoftwareFoundation.Python.3.13_qbz5n2kfra8p0\LocalCache\local-packages\Python313\site-packages\urllib3\connection.py", line 198, in _new_conn
    sock = connection.create_connection(
        (self._dns_host, self.port),
    ...<2 lines>...
        socket_options=self.socket_options,
    )
  File "C:\Users\RohanThomas\AppData\Local\Packages\PythonSoftwareFoundation.Python.3.13_qbz5n2kfra8p0\LocalCache\local-packages\Python313\site-packages\urllib3\util\connection.py", line 85, in create_connection
    raise err
  File "C:\Users\RohanThomas\AppData\Local\Packages\PythonSoftwareFoundation.Python.3.13_qbz5n2kfra8p0\LocalCache\local-packages\Python313\site-packages\urllib3\util\connection.py", line 73, in create_connection
    sock.connect(sa)
    ~~~~~~~~~~~~^^^^
ConnectionRefusedError: [WinError 10061] No connection could be made because the target machine actively refused it

The above exception was the direct cause of the following exception:

Traceback (most recent call last):
  File "C:\Users\RohanThomas\AppData\Local\Packages\PythonSoftwareFoundation.Python.3.13_qbz5n2kfra8p0\LocalCache\local-packages\Python313\site-packages\urllib3\connectionpool.py", line 787, in urlopen
    response = self._make_request(
        conn,
    ...<10 lines>...
        **response_kw,
    )
  File "C:\Users\RohanThomas\AppData\Local\Packages\PythonSoftwareFoundation.Python.3.13_qbz5n2kfra8p0\LocalCache\local-packages\Python313\site-packages\urllib3\connectionpool.py", line 493, in _make_request
    conn.request(
    ~~~~~~~~~~~~^
        method,
        ^^^^^^^
    ...<6 lines>...
        enforce_content_length=enforce_content_length,
        ^^^^^^^^^^^^^^^^^^^^^^^^^^^^^^^^^^^^^^^^^^^^^^
    )
    ^
  File "C:\Users\RohanThomas\AppData\Local\Packages\PythonSoftwareFoundation.Python.3.13_qbz5n2kfra8p0\LocalCache\local-packages\Python313\site-packages\urllib3\connection.py", line 445, in request
    self.endheaders()
    ~~~~~~~~~~~~~~~^^
  File "C:\Program Files\WindowsApps\PythonSoftwareFoundation.Python.3.13_3.13.1008.0_x64__qbz5n2kfra8p0\Lib\http\client.py", line 1333, in endheaders
    self._send_output(message_body, encode_chunked=encode_chunked)
    ~~~~~~~~~~~~~~~~~^^^^^^^^^^^^^^^^^^^^^^^^^^^^^^^^^^^^^^^^^^^^^
  File "C:\Program Files\WindowsApps\PythonSoftwareFoundation.Python.3.13_3.13.1008.0_x64__qbz5n2kfra8p0\Lib\http\client.py", line 1093, in _send_output
    self.send(msg)
    ~~~~~~~~~^^^^^
  File "C:\Program Files\WindowsApps\PythonSoftwareFoundation.Python.3.13_3.13.1008.0_x64__qbz5n2kfra8p0\Lib\http\client.py", line 1037, in send
    self.connect()
    ~~~~~~~~~~~~^^
  File "C:\Users\RohanThomas\AppData\Local\Packages\PythonSoftwareFoundation.Python.3.13_qbz5n2kfra8p0\LocalCache\local-packages\Python313\site-packages\urllib3\connection.py", line 276, in connect
    self.sock = self._new_conn()
                ~~~~~~~~~~~~~~^^
  File "C:\Users\RohanThomas\AppData\Local\Packages\PythonSoftwareFoundation.Python.3.13_qbz5n2kfra8p0\LocalCache\local-packages\Python313\site-packages\urllib3\connection.py", line 213, in _new_conn
    raise NewConnectionError(
        self, f"Failed to establish a new connection: {e}"
    ) from e
urllib3.exceptions.NewConnectionError: <urllib3.connection.HTTPConnection object at 0x0000021FB3B59CD0>: Failed to establish a new connection: [WinError 10061] No connection could be made because the target machine actively refused it

The above exception was the direct cause of the following exception:

Traceback (most recent call last):
  File "C:\Code\New folder\src\winappdriver-testing\windows_automation\test_windows.py", line 75, in test_winforms_app
    driver = create_windows_driver(TEST_CONFIG)
  File "C:\Code\New folder\src\winappdriver-testing\windows_automation\windows_driver_factory.py", line 118, in create_windows_driver
    driver = create_remote_windows_driver(req, options, hub_url)
  File "C:\Code\New folder\src\winappdriver-testing\windows_automation\windows_driver_factory.py", line 144, in create_remote_windows_driver
    appium_driver = webdriver.Remote(
        command_executor=hub_url,
        options=options
    )
  File "C:\Users\RohanThomas\AppData\Local\Packages\PythonSoftwareFoundation.Python.3.13_qbz5n2kfra8p0\LocalCache\local-packages\Python313\site-packages\appium\webdriver\webdriver.py", line 238, in __init__
    super().__init__(
    ~~~~~~~~~~~~~~~~^
        command_executor=command_executor,
        ^^^^^^^^^^^^^^^^^^^^^^^^^^^^^^^^^^
    ...<3 lines>...
        client_config=client_config,
        ^^^^^^^^^^^^^^^^^^^^^^^^^^^^
    )
    ^
  File "C:\Users\RohanThomas\AppData\Local\Packages\PythonSoftwareFoundation.Python.3.13_qbz5n2kfra8p0\LocalCache\local-packages\Python313\site-packages\selenium\webdriver\remote\webdriver.py", line 257, in __init__
    self.start_session(capabilities)
    ~~~~~~~~~~~~~~~~~~^^^^^^^^^^^^^^
  File "C:\Users\RohanThomas\AppData\Local\Packages\PythonSoftwareFoundation.Python.3.13_qbz5n2kfra8p0\LocalCache\local-packages\Python313\site-packages\appium\webdriver\webdriver.py", line 329, in start_session
    response = self.execute(RemoteCommand.NEW_SESSION, w3c_caps)
  File "C:\Users\RohanThomas\AppData\Local\Packages\PythonSoftwareFoundation.Python.3.13_qbz5n2kfra8p0\LocalCache\local-packages\Python313\site-packages\selenium\webdriver\remote\webdriver.py", line 445, in execute
    response = self.command_executor.execute(driver_command, params)
  File "C:\Users\RohanThomas\AppData\Local\Packages\PythonSoftwareFoundation.Python.3.13_qbz5n2kfra8p0\LocalCache\local-packages\Python313\site-packages\selenium\webdriver\remote\remote_connection.py", line 404, in execute
    return self._request(command_info[0], url, body=data)
           ~~~~~~~~~~~~~^^^^^^^^^^^^^^^^^^^^^^^^^^^^^^^^^
  File "C:\Users\RohanThomas\AppData\Local\Packages\PythonSoftwareFoundation.Python.3.13_qbz5n2kfra8p0\LocalCache\local-packages\Python313\site-packages\selenium\webdriver\remote\remote_connection.py", line 428, in _request
    response = self._conn.request(method, url, body=body, headers=headers, timeout=self._client_config.timeout)
  File "C:\Users\RohanThomas\AppData\Local\Packages\PythonSoftwareFoundation.Python.3.13_qbz5n2kfra8p0\LocalCache\local-packages\Python313\site-packages\urllib3\_request_methods.py", line 143, in request
    return self.request_encode_body(
           ~~~~~~~~~~~~~~~~~~~~~~~~^
        method, url, fields=fields, headers=headers, **urlopen_kw
        ^^^^^^^^^^^^^^^^^^^^^^^^^^^^^^^^^^^^^^^^^^^^^^^^^^^^^^^^^
    )
    ^
  File "C:\Users\RohanThomas\AppData\Local\Packages\PythonSoftwareFoundation.Python.3.13_qbz5n2kfra8p0\LocalCache\local-packages\Python313\site-packages\urllib3\_request_methods.py", line 278, in request_encode_body
    return self.urlopen(method, url, **extra_kw)
           ~~~~~~~~~~~~^^^^^^^^^^^^^^^^^^^^^^^^^
  File "C:\Users\RohanThomas\AppData\Local\Packages\PythonSoftwareFoundation.Python.3.13_qbz5n2kfra8p0\LocalCache\local-packages\Python313\site-packages\urllib3\poolmanager.py", line 443, in urlopen
    response = conn.urlopen(method, u.request_uri, **kw)
  File "C:\Users\RohanThomas\AppData\Local\Packages\PythonSoftwareFoundation.Python.3.13_qbz5n2kfra8p0\LocalCache\local-packages\Python313\site-packages\urllib3\connectionpool.py", line 871, in urlopen
    return self.urlopen(
           ~~~~~~~~~~~~^
        method,
        ^^^^^^^
    ...<13 lines>...
        **response_kw,
        ^^^^^^^^^^^^^^
    )
    ^
  File "C:\Users\RohanThomas\AppData\Local\Packages\PythonSoftwareFoundation.Python.3.13_qbz5n2kfra8p0\LocalCache\local-packages\Python313\site-packages\urllib3\connectionpool.py", line 871, in urlopen
    return self.urlopen(
           ~~~~~~~~~~~~^
        method,
        ^^^^^^^
    ...<13 lines>...
        **response_kw,
        ^^^^^^^^^^^^^^
    )
    ^
  File "C:\Users\RohanThomas\AppData\Local\Packages\PythonSoftwareFoundation.Python.3.13_qbz5n2kfra8p0\LocalCache\local-packages\Python313\site-packages\urllib3\connectionpool.py", line 871, in urlopen
    return self.urlopen(
           ~~~~~~~~~~~~^
        method,
        ^^^^^^^
    ...<13 lines>...
        **response_kw,
        ^^^^^^^^^^^^^^
    )
    ^
  File "C:\Users\RohanThomas\AppData\Local\Packages\PythonSoftwareFoundation.Python.3.13_qbz5n2kfra8p0\LocalCache\local-packages\Python313\site-packages\urllib3\connectionpool.py", line 841, in urlopen
    retries = retries.increment(
        method, url, error=new_e, _pool=self, _stacktrace=sys.exc_info()[2]
    )
  File "C:\Users\RohanThomas\AppData\Local\Packages\PythonSoftwareFoundation.Python.3.13_qbz5n2kfra8p0\LocalCache\local-packages\Python313\site-packages\urllib3\util\retry.py", line 519, in increment
    raise MaxRetryError(_pool, url, reason) from reason  # type: ignore[arg-type]
    ^^^^^^^^^^^^^^^^^^^^^^^^^^^^^^^^^^^^^^^^^^^^^^^^^^^
urllib3.exceptions.MaxRetryError: HTTPConnectionPool(host='127.0.0.1', port=4721): Max retries exceeded with url: /session (Caused by NewConnectionError('<urllib3.connection.HTTPConnection object at 0x0000021FB3B59CD0>: Failed to establish a new connection: [WinError 10061] No connection could be made because the target machine actively refused it'))
